Traceback (most recent call last):
  File "/Users/B149899/.pyenv/versions/3.8.2/lib/python3.8/site-packages/jupyter_cache/executors/utils.py", line 51, in single_nb_execution
    executenb(
  File "/Users/B149899/.pyenv/versions/3.8.2/lib/python3.8/site-packages/nbclient/client.py", line 1082, in execute
    return NotebookClient(nb=nb, resources=resources, km=km, **kwargs).execute()
  File "/Users/B149899/.pyenv/versions/3.8.2/lib/python3.8/site-packages/nbclient/util.py", line 74, in wrapped
    return just_run(coro(*args, **kwargs))
  File "/Users/B149899/.pyenv/versions/3.8.2/lib/python3.8/site-packages/nbclient/util.py", line 53, in just_run
    return loop.run_until_complete(coro)
  File "/Users/B149899/.pyenv/versions/3.8.2/lib/python3.8/asyncio/base_events.py", line 616, in run_until_complete
    return future.result()
  File "/Users/B149899/.pyenv/versions/3.8.2/lib/python3.8/site-packages/nbclient/client.py", line 535, in async_execute
    await self.async_execute_cell(
  File "/Users/B149899/.pyenv/versions/3.8.2/lib/python3.8/site-packages/nbclient/client.py", line 827, in async_execute_cell
    self._check_raise_for_error(cell, exec_reply)
  File "/Users/B149899/.pyenv/versions/3.8.2/lib/python3.8/site-packages/nbclient/client.py", line 735, in _check_raise_for_error
    raise CellExecutionError.from_cell_and_msg(cell, exec_reply['content'])
nbclient.exceptions.CellExecutionError: An error occurred while executing the following cell:
------------------
from getpass import getpass
import pandas as pd
from gremlin_python.driver import client, serializer
import gremlin_python.structure.io.graphsonV2d0 as graphsonV2d0
import requests
import time

import deetly

from settings import cosmosdb_conn
------------------

[0;31m---------------------------------------------------------------------------[0m
[0;31mModuleNotFoundError[0m                       Traceback (most recent call last)
[0;32m<ipython-input-1-b394807f0f8a>[0m in [0;36m<module>[0;34m[0m
[1;32m      8[0m [0;32mimport[0m [0mdeetly[0m[0;34m[0m[0;34m[0m[0m
[1;32m      9[0m [0;34m[0m[0m
[0;32m---> 10[0;31m [0;32mfrom[0m [0msettings[0m [0;32mimport[0m [0mcosmosdb_conn[0m[0;34m[0m[0;34m[0m[0m
[0m
[0;31mModuleNotFoundError[0m: No module named 'settings'
ModuleNotFoundError: No module named 'settings'

