Traceback (most recent call last):
  File "/opt/hostedtoolcache/Python/3.7.9/x64/lib/python3.7/site-packages/jupyter_cache/executors/utils.py", line 56, in single_nb_execution
    record_timing=False,
  File "/opt/hostedtoolcache/Python/3.7.9/x64/lib/python3.7/site-packages/nbclient/client.py", line 1087, in execute
    return NotebookClient(nb=nb, resources=resources, km=km, **kwargs).execute()
  File "/opt/hostedtoolcache/Python/3.7.9/x64/lib/python3.7/site-packages/nbclient/util.py", line 74, in wrapped
    return just_run(coro(*args, **kwargs))
  File "/opt/hostedtoolcache/Python/3.7.9/x64/lib/python3.7/site-packages/nbclient/util.py", line 53, in just_run
    return loop.run_until_complete(coro)
  File "/opt/hostedtoolcache/Python/3.7.9/x64/lib/python3.7/asyncio/base_events.py", line 587, in run_until_complete
    return future.result()
  File "/opt/hostedtoolcache/Python/3.7.9/x64/lib/python3.7/site-packages/nbclient/client.py", line 541, in async_execute
    cell, index, execution_count=self.code_cells_executed + 1
  File "/opt/hostedtoolcache/Python/3.7.9/x64/lib/python3.7/site-packages/nbclient/client.py", line 832, in async_execute_cell
    self._check_raise_for_error(cell, exec_reply)
  File "/opt/hostedtoolcache/Python/3.7.9/x64/lib/python3.7/site-packages/nbclient/client.py", line 740, in _check_raise_for_error
    raise CellExecutionError.from_cell_and_msg(cell, exec_reply['content'])
nbclient.exceptions.CellExecutionError: An error occurred while executing the following cell:
------------------
import deetly
import pandas as pd
import altair as alt
import dateutil.parser
import requests
import json
from pyjstat import pyjstat

from datetime import datetime
import time

import locale
locale.setlocale(locale.LC_ALL, "no_NO.UTF-8")
------------------

[0;31m---------------------------------------------------------------------------[0m
[0;31mError[0m                                     Traceback (most recent call last)
[0;32m<ipython-input-1-709b747a999d>[0m in [0;36m<module>[0;34m[0m
[1;32m     11[0m [0;34m[0m[0m
[1;32m     12[0m [0;32mimport[0m [0mlocale[0m[0;34m[0m[0;34m[0m[0m
[0;32m---> 13[0;31m [0mlocale[0m[0;34m.[0m[0msetlocale[0m[0;34m([0m[0mlocale[0m[0;34m.[0m[0mLC_ALL[0m[0;34m,[0m [0;34m"no_NO.UTF-8"[0m[0;34m)[0m[0;34m[0m[0;34m[0m[0m
[0m
[0;32m/opt/hostedtoolcache/Python/3.7.9/x64/lib/python3.7/locale.py[0m in [0;36msetlocale[0;34m(category, locale)[0m
[1;32m    606[0m         [0;31m# convert to string[0m[0;34m[0m[0;34m[0m[0;34m[0m[0m
[1;32m    607[0m         [0mlocale[0m [0;34m=[0m [0mnormalize[0m[0;34m([0m[0m_build_localename[0m[0;34m([0m[0mlocale[0m[0;34m)[0m[0;34m)[0m[0;34m[0m[0;34m[0m[0m
[0;32m--> 608[0;31m     [0;32mreturn[0m [0m_setlocale[0m[0;34m([0m[0mcategory[0m[0;34m,[0m [0mlocale[0m[0;34m)[0m[0;34m[0m[0;34m[0m[0m
[0m[1;32m    609[0m [0;34m[0m[0m
[1;32m    610[0m [0;32mdef[0m [0mresetlocale[0m[0;34m([0m[0mcategory[0m[0;34m=[0m[0mLC_ALL[0m[0;34m)[0m[0;34m:[0m[0;34m[0m[0;34m[0m[0m

[0;31mError[0m: unsupported locale setting
Error: unsupported locale setting

