Traceback (most recent call last):
  File "/opt/hostedtoolcache/Python/3.7.10/x64/lib/python3.7/site-packages/jupyter_cache/executors/utils.py", line 56, in single_nb_execution
    record_timing=False,
  File "/opt/hostedtoolcache/Python/3.7.10/x64/lib/python3.7/site-packages/nbclient/client.py", line 1112, in execute
    return NotebookClient(nb=nb, resources=resources, km=km, **kwargs).execute()
  File "/opt/hostedtoolcache/Python/3.7.10/x64/lib/python3.7/site-packages/nbclient/util.py", line 74, in wrapped
    return just_run(coro(*args, **kwargs))
  File "/opt/hostedtoolcache/Python/3.7.10/x64/lib/python3.7/site-packages/nbclient/util.py", line 53, in just_run
    return loop.run_until_complete(coro)
  File "/opt/hostedtoolcache/Python/3.7.10/x64/lib/python3.7/asyncio/base_events.py", line 587, in run_until_complete
    return future.result()
  File "/opt/hostedtoolcache/Python/3.7.10/x64/lib/python3.7/site-packages/nbclient/client.py", line 554, in async_execute
    cell, index, execution_count=self.code_cells_executed + 1
  File "/opt/hostedtoolcache/Python/3.7.10/x64/lib/python3.7/site-packages/nbclient/client.py", line 857, in async_execute_cell
    self._check_raise_for_error(cell, exec_reply)
  File "/opt/hostedtoolcache/Python/3.7.10/x64/lib/python3.7/site-packages/nbclient/client.py", line 760, in _check_raise_for_error
    raise CellExecutionError.from_cell_and_msg(cell, exec_reply_content)
nbclient.exceptions.CellExecutionError: An error occurred while executing the following cell:
------------------
import deetly
import requests
import tempfile
import shutil
import pm4py
import pandas as pd

from pm4py.statistics.attributes.log import get as attributes_filter
from pm4py.objects.log.importer.xes import importer as xes_importer
from pm4py.statistics.traces.log import case_statistics
from pm4py.visualization.graphs import visualizer as graphs_visualizer
------------------

[0;31m---------------------------------------------------------------------------[0m
[0;31mModuleNotFoundError[0m                       Traceback (most recent call last)
[0;32m<ipython-input-1-52801a73e480>[0m in [0;36m<module>[0;34m[0m
[1;32m      3[0m [0;32mimport[0m [0mtempfile[0m[0;34m[0m[0;34m[0m[0m
[1;32m      4[0m [0;32mimport[0m [0mshutil[0m[0;34m[0m[0;34m[0m[0m
[0;32m----> 5[0;31m [0;32mimport[0m [0mpm4py[0m[0;34m[0m[0;34m[0m[0m
[0m[1;32m      6[0m [0;32mimport[0m [0mpandas[0m [0;32mas[0m [0mpd[0m[0;34m[0m[0;34m[0m[0m
[1;32m      7[0m [0;34m[0m[0m

[0;31mModuleNotFoundError[0m: No module named 'pm4py'
ModuleNotFoundError: No module named 'pm4py'

